<?xml version="1.0"?>
<robot name="differential_robot">

<!-- Differential robot model with trasmission tag to run programs but they aren't functional yet  -->
    <material name="red">
        <color rgba="1 0 0 1"/>
    </material>
    <material name="black">
        <color rgba="0 0 0 1"/>
    </material>
    <material name="white">
        <color rgba="1 1 1 1"/>
    </material>
    <material name="blue">
        <color rgba="0 0 1 1"/>
    </material>
    <material name="gray">
        <color rgba="0.6 0.6 0.6 1"/>
    </material>

    <link name="base_footprint">
        <visual>
            <geometry>
                <box size="0.001 0.001 0.001"/>
            </geometry>
            <origin rpy="0 0 0" xyz="0 0 0"/>
            <material name="white"/>
        </visual>
        <collision>
            <geometry>
                <box size="0.001 0.001 0.001"/>
            </geometry>
            <origin rpy="0 0 0" xyz="0 0 0"/>
        </collision>
        <inertial>
            <mass value="0.0001"/>
            <inertia ixx="0.0001" ixy="0.0" ixz="0.0" iyy="0.0001" iyz="0.0" izz="0.0001"/>
            <origin xyz="0 0 0"/>
        </inertial>
    </link>

    <joint name="base_footprint_joint" type="fixed">
        <parent link="base_footprint"/>
        <child link="base_link"/>
        <origin rpy="0 0 0" xyz="0 0 0.04"/>
    </joint>

    <link name="base_link">
        <visual>
            <geometry>
                <cylinder length="0.02" radius="0.15"/>
            </geometry>
            <origin rpy="0 0 0" xyz="0 0 0"/>
            <material name="white"/>
        </visual>
        <collision>
            <geometry>
                <cylinder length="0.02" radius="0.15"/>
            </geometry>
            <origin rpy="0 0 0" xyz="0 0 0"/>
        </collision>
        <inertial>
            <mass value="5"/>
            <inertia ixx="0.0282916666667" ixy="0" ixz="0" iyy="0.0282916666667" iyz="0" izz="0.05625"/>
            <origin xyz="0 0 0"/>
        </inertial>
    </link>

    <joint name="front_right_wheel_joint" type="continuous">
        <parent link="base_link"/>
        <child link="front_right_wheel"/>
        <origin rpy="0 0 0" xyz="0 -0.15 0" />
        <axis rpy="0  0" xyz="0 1 0"/>
        <limit effort="100" velocity="100"/>
        <joint_properties damping="0.0" friction="0.0"/>
    </joint>

    <joint name="front_left_wheel_joint" type="continuous">
        <parent link="base_link"/>
        <child link="front_left_wheel"/>
        <origin rpy="0 0 0" xyz="0 0.15 0" />
        <axis rpy="0  0" xyz="0 1 0"/>
        <limit effort="100" velocity="100"/>
        <joint_properties damping="0.0" friction="0.0"/>
    </joint>

    <transmission name="front_right_wheel_joint_trans">
        <type>transmission_interface/SimpleTransmission</type>
        <joint name="front_right_wheel_joint"/>
        <actuator name="front_right_wheel_joint_motor">
            <hardwareInterface>EffortJointInterface</hardwareInterface>
            <mechanicalReduction>1</mechanicalReduction>
        </actuator>
    </transmission>

    <transmission name="front_left_wheel_joint_trans">
        <type>transmission_interface/SimpleTransmission</type>
        <joint name="front_left_wheel_joint"/>
        <actuator name="front_left_wheel_joint_motor">
            <hardwareInterface>EffortJointInterface</hardwareInterface>
            <mechanicalReduction>1</mechanicalReduction>
        </actuator>
    </transmission>

    <link name="front_right_wheel">
        <visual>
            <geometry>
                <cylinder length="0.02" radius="0.04"/>
            </geometry>
            <origin rpy="1.57079632679 0  0 " xyz="0 0 0"/>
            <material name="gray"/>
        </visual>
        <collision>
            <geometry>
                <cylinder length="0.02" radius="0.04"/>
            </geometry>
            <origin rpy="1.57079632679 0  0 " xyz="0 0 0"/>
        </collision>
        <inertial>
            <mass value="2.5"/>
            <inertia ixx="0.00108333333333" ixy="0" ixz="0" iyy="0.00108333333333" iyz="0" izz="0.002"/>
            <origin xyz="0 0 0"/>
        </inertial>
    </link>
    
    <link name="front_left_wheel">
        <visual>
            <geometry>
                <cylinder length="0.02" radius="0.04"/>
            </geometry>
            <origin rpy="1.57079632679 0  0 " xyz="0 0 0"/>
            <material name="gray"/>
        </visual>
        <collision>
            <geometry>
                <cylinder length="0.02" radius="0.04"/>
            </geometry>
            <origin rpy="1.57079632679 0  0 " xyz="0 0 0"/>
        </collision>
        <inertial>
            <mass value="2.5"/>
            <inertia ixx="0.00108333333333" ixy="0" ixz="0" iyy="0.00108333333333" iyz="0" izz="0.002"/>
            <origin xyz="0 0 0"/>
        </inertial>
    </link>

    <joint name="caster_front_joint" type="fixed">
        <parent link="base_link"/>
        <child link="caster_front_link"/>
        <origin rpy="-1.57079632679 0 0" xyz="0.115 0.0 0.007"/>
    </joint>

    <joint name="caster_back_joint" type="fixed">
        <parent link="base_link"/>
        <child link="caster_back_link"/>
        <origin rpy="-1.57079632679 0 0" xyz="-0.135 0.0 0.009"/>
    </joint>

    <link name="caster_front_link">
        <visual>
            <origin rpy="1.57079632679 0 0" xyz="0 0.02 0"/>
            <geometry>
              <sphere radius="0.025"/>
            </geometry>
            <material name="black"/>
        </visual>
        <collision>
            <geometry>
              <sphere radius="0.025"/>
            </geometry>
            <origin rpy="1.57079632679 0 0" xyz="0 0.02 0"/>
        </collision>
        <inertial>
            <mass value="0.5"/>
            <origin xyz="0 0 0"/>
            <inertia ixx="0.001" ixy="0.0" ixz="0.0" iyy="0.001" iyz="0.0" izz="0.001"/>
        </inertial>
    </link>

    <link name="caster_back_link">
        <visual>
            <origin rpy="1.57079632679 0 0" xyz="0.02 0.02 0 "/>
            <geometry>
              <sphere radius="0.025"/>
            </geometry>
            <material name="black"/>
        </visual>
        <collision>
            <geometry>
              <sphere radius="0.025"/>
            </geometry>
            <origin rpy="1.57079632679 0 0" xyz="0 0.02 0"/>
        </collision>
        <inertial>
            <mass value="0.5"/>
            <origin xyz="0 0 0"/>
            <inertia ixx="0.001" ixy="0.0" ixz="0.0" iyy="0.001" iyz="0.0" izz="0.001"/>
        </inertial>
    </link>

</robot>
